2025-06-24 15:10:30,206 INFO    MainThread:80031 [wandb_setup.py:_flush():68] Current SDK version is 0.19.1
2025-06-24 15:10:30,207 INFO    MainThread:80031 [wandb_setup.py:_flush():68] Configure stats pid to 80031
2025-06-24 15:10:30,207 INFO    MainThread:80031 [wandb_setup.py:_flush():68] Loading settings from /Users/huiyufei/.config/wandb/settings
2025-06-24 15:10:30,207 INFO    MainThread:80031 [wandb_setup.py:_flush():68] Loading settings from /Users/huiyufei/Desktop/mini_audio_caption/wandb/settings
2025-06-24 15:10:30,207 INFO    MainThread:80031 [wandb_setup.py:_flush():68] Loading settings from environment variables
2025-06-24 15:10:30,207 INFO    MainThread:80031 [wandb_init.py:_log_setup():528] Logging user logs to /Users/huiyufei/Desktop/mini_audio_caption/wandb/run-20250624_151030-pypmfgqt/logs/debug.log
2025-06-24 15:10:30,207 INFO    MainThread:80031 [wandb_init.py:_log_setup():529] Logging internal logs to /Users/huiyufei/Desktop/mini_audio_caption/wandb/run-20250624_151030-pypmfgqt/logs/debug-internal.log
2025-06-24 15:10:30,207 INFO    MainThread:80031 [wandb_init.py:init():644] calling init triggers
2025-06-24 15:10:30,207 INFO    MainThread:80031 [wandb_init.py:init():650] wandb.init called with sweep_config: {}
config: {}
2025-06-24 15:10:30,207 INFO    MainThread:80031 [wandb_init.py:init():680] starting backend
2025-06-24 15:10:30,207 INFO    MainThread:80031 [wandb_init.py:init():684] sending inform_init request
2025-06-24 15:10:30,257 INFO    MainThread:80031 [backend.py:_multiprocessing_setup():104] multiprocessing start_methods=spawn,fork,forkserver, using: spawn
2025-06-24 15:10:30,258 INFO    MainThread:80031 [wandb_init.py:init():697] backend started and connected
2025-06-24 15:10:30,262 INFO    MainThread:80031 [wandb_init.py:init():790] updated telemetry
2025-06-24 15:10:30,287 INFO    MainThread:80031 [wandb_init.py:init():822] communicating run to backend with 120.0 second timeout
2025-06-24 15:11:28,766 INFO    Thread-1 (wrapped_target):80031 [retry.py:__call__():172] Retry attempt failed:
Traceback (most recent call last):
  File "/opt/anaconda3/envs/audio_caption/lib/python3.10/site-packages/urllib3/connection.py", line 198, in _new_conn
    sock = connection.create_connection(
  File "/opt/anaconda3/envs/audio_caption/lib/python3.10/site-packages/urllib3/util/connection.py", line 85, in create_connection
    raise err
  File "/opt/anaconda3/envs/audio_caption/lib/python3.10/site-packages/urllib3/util/connection.py", line 73, in create_connection
    sock.connect(sa)
TimeoutError: timed out

The above exception was the direct cause of the following exception:

Traceback (most recent call last):
  File "/opt/anaconda3/envs/audio_caption/lib/python3.10/site-packages/urllib3/connectionpool.py", line 787, in urlopen
    response = self._make_request(
  File "/opt/anaconda3/envs/audio_caption/lib/python3.10/site-packages/urllib3/connectionpool.py", line 488, in _make_request
    raise new_e
  File "/opt/anaconda3/envs/audio_caption/lib/python3.10/site-packages/urllib3/connectionpool.py", line 464, in _make_request
    self._validate_conn(conn)
  File "/opt/anaconda3/envs/audio_caption/lib/python3.10/site-packages/urllib3/connectionpool.py", line 1093, in _validate_conn
    conn.connect()
  File "/opt/anaconda3/envs/audio_caption/lib/python3.10/site-packages/urllib3/connection.py", line 704, in connect
    self.sock = sock = self._new_conn()
  File "/opt/anaconda3/envs/audio_caption/lib/python3.10/site-packages/urllib3/connection.py", line 207, in _new_conn
    raise ConnectTimeoutError(
urllib3.exceptions.ConnectTimeoutError: (<urllib3.connection.HTTPSConnection object at 0x13defb430>, 'Connection to api.wandb.ai timed out. (connect timeout=20)')

The above exception was the direct cause of the following exception:

Traceback (most recent call last):
  File "/opt/anaconda3/envs/audio_caption/lib/python3.10/site-packages/requests/adapters.py", line 667, in send
    resp = conn.urlopen(
  File "/opt/anaconda3/envs/audio_caption/lib/python3.10/site-packages/urllib3/connectionpool.py", line 841, in urlopen
    retries = retries.increment(
  File "/opt/anaconda3/envs/audio_caption/lib/python3.10/site-packages/urllib3/util/retry.py", line 519, in increment
    raise MaxRetryError(_pool, url, reason) from reason  # type: ignore[arg-type]
urllib3.exceptions.MaxRetryError: HTTPSConnectionPool(host='api.wandb.ai', port=443): Max retries exceeded with url: /graphql (Caused by ConnectTimeoutError(<urllib3.connection.HTTPSConnection object at 0x13defb430>, 'Connection to api.wandb.ai timed out. (connect timeout=20)'))

During handling of the above exception, another exception occurred:

Traceback (most recent call last):
  File "/opt/anaconda3/envs/audio_caption/lib/python3.10/site-packages/wandb/sdk/lib/retry.py", line 131, in __call__
    result = self._call_fn(*args, **kwargs)
  File "/opt/anaconda3/envs/audio_caption/lib/python3.10/site-packages/wandb/sdk/internal/internal_api.py", line 393, in execute
    return self.client.execute(*args, **kwargs)  # type: ignore
  File "/opt/anaconda3/envs/audio_caption/lib/python3.10/site-packages/wandb/vendor/gql-0.2.0/wandb_gql/client.py", line 52, in execute
    result = self._get_result(document, *args, **kwargs)
  File "/opt/anaconda3/envs/audio_caption/lib/python3.10/site-packages/wandb/vendor/gql-0.2.0/wandb_gql/client.py", line 60, in _get_result
    return self.transport.execute(document, *args, **kwargs)
  File "/opt/anaconda3/envs/audio_caption/lib/python3.10/site-packages/wandb/sdk/lib/gql_request.py", line 58, in execute
    request = self.session.post(self.url, **post_args)
  File "/opt/anaconda3/envs/audio_caption/lib/python3.10/site-packages/requests/sessions.py", line 637, in post
    return self.request("POST", url, data=data, json=json, **kwargs)
  File "/opt/anaconda3/envs/audio_caption/lib/python3.10/site-packages/requests/sessions.py", line 589, in request
    resp = self.send(prep, **send_kwargs)
  File "/opt/anaconda3/envs/audio_caption/lib/python3.10/site-packages/requests/sessions.py", line 703, in send
    r = adapter.send(request, **kwargs)
  File "/opt/anaconda3/envs/audio_caption/lib/python3.10/site-packages/requests/adapters.py", line 688, in send
    raise ConnectTimeout(e, request=request)
requests.exceptions.ConnectTimeout: HTTPSConnectionPool(host='api.wandb.ai', port=443): Max retries exceeded with url: /graphql (Caused by ConnectTimeoutError(<urllib3.connection.HTTPSConnection object at 0x13defb430>, 'Connection to api.wandb.ai timed out. (connect timeout=20)'))
2025-06-24 15:12:30,840 ERROR   MainThread:80031 [wandb_init.py:init():849] encountered error: Run initialization has timed out after 120.0 sec. Please try increasing the timeout with the `init_timeout` setting: `wandb.init(settings=wandb.Settings(init_timeout=120))`.
2025-06-24 15:12:30,841 ERROR   MainThread:80031 [wandb_init.py:init():1308] error in wandb.init()
Traceback (most recent call last):
  File "/opt/anaconda3/envs/audio_caption/lib/python3.10/site-packages/wandb/sdk/wandb_init.py", line 1298, in init
    return wi.init()
  File "/opt/anaconda3/envs/audio_caption/lib/python3.10/site-packages/wandb/sdk/wandb_init.py", line 855, in init
    raise error
wandb.errors.errors.CommError: Run initialization has timed out after 120.0 sec. Please try increasing the timeout with the `init_timeout` setting: `wandb.init(settings=wandb.Settings(init_timeout=120))`.
2025-06-24 15:12:30,872 WARNING MsgRouterThr:80031 [router.py:message_loop():75] message_loop has been closed
